2021-08-03 10:49:06,910 ERROR: Exception on /login [POST] [in /home/stefan/PycharmProjects/Flask/venv/lib/python3.6/site-packages/flask/app.py:1455]
Traceback (most recent call last):
  File "/home/stefan/PycharmProjects/Flask/venv/lib/python3.6/site-packages/flask/app.py", line 2070, in wsgi_app
    response = self.full_dispatch_request()
  File "/home/stefan/PycharmProjects/Flask/venv/lib/python3.6/site-packages/flask/app.py", line 1515, in full_dispatch_request
    rv = self.handle_user_exception(e)
  File "/home/stefan/PycharmProjects/Flask/venv/lib/python3.6/site-packages/flask/app.py", line 1513, in full_dispatch_request
    rv = self.dispatch_request()
  File "/home/stefan/PycharmProjects/Flask/venv/lib/python3.6/site-packages/flask/app.py", line 1499, in dispatch_request
    return self.ensure_sync(self.view_functions[rule.endpoint])(**req.view_args)
  File "/home/stefan/PycharmProjects/Flask/app/routes.py", line 34, in login
    if user is None or not user.check_password(form.password.data):
  File "/home/stefan/PycharmProjects/Flask/app/models.py", line 36, in check_password
    return check_password_hash(self.password_hash, password)
  File "/home/stefan/PycharmProjects/Flask/venv/lib/python3.6/site-packages/werkzeug/security.py", line 215, in check_password_hash
    if pwhash.count("$") < 2:
AttributeError: 'NoneType' object has no attribute 'count'
2021-08-03 10:51:05,221 ERROR: Exception on /login [POST] [in /home/stefan/PycharmProjects/Flask/venv/lib/python3.6/site-packages/flask/app.py:1455]
Traceback (most recent call last):
  File "/home/stefan/PycharmProjects/Flask/venv/lib/python3.6/site-packages/flask/app.py", line 2070, in wsgi_app
    response = self.full_dispatch_request()
  File "/home/stefan/PycharmProjects/Flask/venv/lib/python3.6/site-packages/flask/app.py", line 1515, in full_dispatch_request
    rv = self.handle_user_exception(e)
  File "/home/stefan/PycharmProjects/Flask/venv/lib/python3.6/site-packages/flask/app.py", line 1513, in full_dispatch_request
    rv = self.dispatch_request()
  File "/home/stefan/PycharmProjects/Flask/venv/lib/python3.6/site-packages/flask/app.py", line 1499, in dispatch_request
    return self.ensure_sync(self.view_functions[rule.endpoint])(**req.view_args)
  File "/home/stefan/PycharmProjects/Flask/app/routes.py", line 34, in login
    if user is None or not user.check_password(form.password.data):
  File "/home/stefan/PycharmProjects/Flask/app/models.py", line 36, in check_password
    return check_password_hash(self.password_hash, password)
  File "/home/stefan/PycharmProjects/Flask/venv/lib/python3.6/site-packages/werkzeug/security.py", line 215, in check_password_hash
    if pwhash.count("$") < 2:
AttributeError: 'NoneType' object has no attribute 'count'
2021-08-03 10:52:48,776 ERROR: Exception on /login [POST] [in /home/stefan/PycharmProjects/Flask/venv/lib/python3.6/site-packages/flask/app.py:1455]
Traceback (most recent call last):
  File "/home/stefan/PycharmProjects/Flask/venv/lib/python3.6/site-packages/flask/app.py", line 2070, in wsgi_app
    response = self.full_dispatch_request()
  File "/home/stefan/PycharmProjects/Flask/venv/lib/python3.6/site-packages/flask/app.py", line 1515, in full_dispatch_request
    rv = self.handle_user_exception(e)
  File "/home/stefan/PycharmProjects/Flask/venv/lib/python3.6/site-packages/flask/app.py", line 1513, in full_dispatch_request
    rv = self.dispatch_request()
  File "/home/stefan/PycharmProjects/Flask/venv/lib/python3.6/site-packages/flask/app.py", line 1499, in dispatch_request
    return self.ensure_sync(self.view_functions[rule.endpoint])(**req.view_args)
  File "/home/stefan/PycharmProjects/Flask/app/routes.py", line 34, in login
    if user is None or not user.check_password(form.password.data):
  File "/home/stefan/PycharmProjects/Flask/app/models.py", line 36, in check_password
    return check_password_hash(self.password_hash, password)
  File "/home/stefan/PycharmProjects/Flask/venv/lib/python3.6/site-packages/werkzeug/security.py", line 215, in check_password_hash
    if pwhash.count("$") < 2:
AttributeError: 'NoneType' object has no attribute 'count'
2021-08-03 10:58:22,405 INFO: Microblog startup [in /home/stefan/PycharmProjects/Flask/app/__init__.py:43]
2021-08-03 10:58:29,696 ERROR: Exception on /login [POST] [in /home/stefan/PycharmProjects/Flask/venv/lib/python3.6/site-packages/flask/app.py:1455]
Traceback (most recent call last):
  File "/home/stefan/PycharmProjects/Flask/venv/lib/python3.6/site-packages/flask/app.py", line 2070, in wsgi_app
    response = self.full_dispatch_request()
  File "/home/stefan/PycharmProjects/Flask/venv/lib/python3.6/site-packages/flask/app.py", line 1515, in full_dispatch_request
    rv = self.handle_user_exception(e)
  File "/home/stefan/PycharmProjects/Flask/venv/lib/python3.6/site-packages/flask/app.py", line 1513, in full_dispatch_request
    rv = self.dispatch_request()
  File "/home/stefan/PycharmProjects/Flask/venv/lib/python3.6/site-packages/flask/app.py", line 1499, in dispatch_request
    return self.ensure_sync(self.view_functions[rule.endpoint])(**req.view_args)
  File "/home/stefan/PycharmProjects/Flask/app/routes.py", line 34, in login
    if user is None or not user.check_password(form.password.data):
  File "/home/stefan/PycharmProjects/Flask/app/models.py", line 36, in check_password
    return check_password_hash(self.password_hash, password)
  File "/home/stefan/PycharmProjects/Flask/venv/lib/python3.6/site-packages/werkzeug/security.py", line 215, in check_password_hash
    if pwhash.count("$") < 2:
AttributeError: 'NoneType' object has no attribute 'count'
2021-08-03 10:59:55,909 INFO: Microblog startup [in /home/stefan/PycharmProjects/Flask/app/__init__.py:43]
2021-08-03 11:00:11,168 INFO: Microblog startup [in /home/stefan/PycharmProjects/Flask/app/__init__.py:43]
2021-08-03 11:26:24,168 INFO: Microblog startup [in /home/stefan/PycharmProjects/Flask/app/__init__.py:43]
2021-08-03 11:26:26,704 ERROR: Exception on / [GET] [in /home/stefan/PycharmProjects/Flask/venv/lib/python3.6/site-packages/flask/app.py:1455]
Traceback (most recent call last):
  File "/home/stefan/PycharmProjects/Flask/venv/lib/python3.6/site-packages/flask/app.py", line 2070, in wsgi_app
    response = self.full_dispatch_request()
  File "/home/stefan/PycharmProjects/Flask/venv/lib/python3.6/site-packages/flask/app.py", line 1515, in full_dispatch_request
    rv = self.handle_user_exception(e)
  File "/home/stefan/PycharmProjects/Flask/venv/lib/python3.6/site-packages/flask/app.py", line 1513, in full_dispatch_request
    rv = self.dispatch_request()
  File "/home/stefan/PycharmProjects/Flask/venv/lib/python3.6/site-packages/flask/app.py", line 1499, in dispatch_request
    return self.ensure_sync(self.view_functions[rule.endpoint])(**req.view_args)
  File "/home/stefan/PycharmProjects/Flask/venv/lib/python3.6/site-packages/flask_login/utils.py", line 272, in decorated_view
    return func(*args, **kwargs)
  File "/home/stefan/PycharmProjects/Flask/app/routes.py", line 25, in index
    page, app.config['POSTS_PER_PAGE'], False
KeyError: 'POSTS_PER_PAGE'
2021-08-03 11:26:30,137 ERROR: Exception on /index [GET] [in /home/stefan/PycharmProjects/Flask/venv/lib/python3.6/site-packages/flask/app.py:1455]
Traceback (most recent call last):
  File "/home/stefan/PycharmProjects/Flask/venv/lib/python3.6/site-packages/flask/app.py", line 2070, in wsgi_app
    response = self.full_dispatch_request()
  File "/home/stefan/PycharmProjects/Flask/venv/lib/python3.6/site-packages/flask/app.py", line 1515, in full_dispatch_request
    rv = self.handle_user_exception(e)
  File "/home/stefan/PycharmProjects/Flask/venv/lib/python3.6/site-packages/flask/app.py", line 1513, in full_dispatch_request
    rv = self.dispatch_request()
  File "/home/stefan/PycharmProjects/Flask/venv/lib/python3.6/site-packages/flask/app.py", line 1499, in dispatch_request
    return self.ensure_sync(self.view_functions[rule.endpoint])(**req.view_args)
  File "/home/stefan/PycharmProjects/Flask/venv/lib/python3.6/site-packages/flask_login/utils.py", line 272, in decorated_view
    return func(*args, **kwargs)
  File "/home/stefan/PycharmProjects/Flask/app/routes.py", line 25, in index
    page, app.config['POSTS_PER_PAGE'], False
KeyError: 'POSTS_PER_PAGE'
2021-08-03 11:26:31,763 ERROR: Exception on /index [GET] [in /home/stefan/PycharmProjects/Flask/venv/lib/python3.6/site-packages/flask/app.py:1455]
Traceback (most recent call last):
  File "/home/stefan/PycharmProjects/Flask/venv/lib/python3.6/site-packages/flask/app.py", line 2070, in wsgi_app
    response = self.full_dispatch_request()
  File "/home/stefan/PycharmProjects/Flask/venv/lib/python3.6/site-packages/flask/app.py", line 1515, in full_dispatch_request
    rv = self.handle_user_exception(e)
  File "/home/stefan/PycharmProjects/Flask/venv/lib/python3.6/site-packages/flask/app.py", line 1513, in full_dispatch_request
    rv = self.dispatch_request()
  File "/home/stefan/PycharmProjects/Flask/venv/lib/python3.6/site-packages/flask/app.py", line 1499, in dispatch_request
    return self.ensure_sync(self.view_functions[rule.endpoint])(**req.view_args)
  File "/home/stefan/PycharmProjects/Flask/venv/lib/python3.6/site-packages/flask_login/utils.py", line 272, in decorated_view
    return func(*args, **kwargs)
  File "/home/stefan/PycharmProjects/Flask/app/routes.py", line 25, in index
    page, app.config['POSTS_PER_PAGE'], False
KeyError: 'POSTS_PER_PAGE'
